<?xml version="1.0"?>
<!-- Auto-generated combined M0609 + RG2 URDF. src_hash=fa2cd0a0df6a gen=v4 -->
<robot name="m0609_rg2">

		<link name="base_link">
			<inertial>
				<mass value="3.18"/>
				<origin xyz="-2.8e-05   -0.006045    0.038403"/>
				<inertia ixx="0.017789" ixy="-7.4356e-06" ixz="3.0378e-06" iyy="0.011135"
					iyz="-0.00029038"
					izz="0.020054"/>
			</inertial>
			<collision>
				<origin rpy="0 0 0" xyz="0 0 0" />
				<geometry>
					<mesh filename="/home/rokey/dev_ws/issac_sim/src/doosan-robot2/urdf/meshes/m0609_collision/MF0609_0_0.dae" scale="0.001 0.001 0.001" />
				</geometry>
			</collision>
			<visual>
				<origin rpy="0 0 0" xyz="0 0 0" />
				<geometry>
					<mesh filename="/home/rokey/dev_ws/issac_sim/src/doosan-robot2/urdf/meshes/m0609_white/MF0609_0_0.dae" scale="0.001 0.001 0.001" />
				</geometry>
			</visual>
		</link>
		<link name="base"/>
		<joint name="base_link-base" type="fixed">
			<origin rpy="0 0 0" xyz="0 0 0.450"/>
			<parent link="base_link"/>
			<child link="base"/>
		</joint>
		<!-- joint 1 -->
		<joint name="joint_1" type="revolute">
			<parent link="base_link" />
			<child link="link_1" />
			<origin rpy="0 0 0" xyz="0 0 0.1345" />
			<axis xyz="0 0 1" />
			<limit effort="9600" lower="-6.2832" upper="6.2832" velocity="2.618"/>
			<dynamics friction="0" damping="26.6667" stiffness="266.6667"/>
		</joint>
		<link name="link_1">
			<inertial>
				<mass value="5.02"/>
				<origin xyz="7.2e-05    0.036227   -0.003417"/>
				<inertia ixx="0.026195" ixy="2.3904e-05" ixz="-1.3319e-05" iyy="0.016899"
					iyz="-0.00071987"
					izz="0.022944"/>
			</inertial>
            <collision>
				<origin rpy="0 0 0" xyz="0 0 0" />
				<geometry>
					<mesh filename="/home/rokey/dev_ws/issac_sim/src/doosan-robot2/urdf/meshes/m0609_collision/MF0609_1_0.dae" scale="0.001 0.001 0.001" />
				</geometry>
			</collision>
			<visual>
				<origin rpy="0 0 0" xyz="0 0 0" />
				<geometry>
					<mesh filename="/home/rokey/dev_ws/issac_sim/src/doosan-robot2/urdf/meshes/m0609_white/MF0609_1_0.dae" scale="0.001 0.001 0.001" />
				</geometry>
			</visual>
		</link>
		<!-- joint2 -->
		<joint name="joint_2" type="revolute">
			<parent link="link_1" />
			<child link="link_2" />
			<origin rpy="0 -1.571 -1.571" xyz="0 0.0062 0" />
			<axis xyz="0 0 1" />
			<limit effort="9600" lower="-6.2832" upper="6.2832" velocity="2.618"/>
			<dynamics friction="0"  damping="26.6667" stiffness="266.6667"/>
		</joint>
		<link name="link_2">
			<inertial>
				<mass value="8.04"/>
				<origin xyz="0.20447     2.6e-05     0.16005"/>
				<inertia ixx="0.026743" ixy="-0.00019461" ixz="-0.00058734" iyy="0.30084"
					iyz="-6.7892e-06"
					izz="0.29898"/>
			</inertial>
            <collision>
				<origin rpy="0 0 0" xyz="0 0 0" />
				<geometry>
					<mesh filename="/home/rokey/dev_ws/issac_sim/src/doosan-robot2/urdf/meshes/m0609_collision/MF0609_2_0.dae" scale="0.001 0.001 0.001" />
				</geometry>
			</collision>
			<visual>
				<origin rpy="0 0 0" xyz="0 0 0" />
				<geometry>
					<mesh filename="/home/rokey/dev_ws/issac_sim/src/doosan-robot2/urdf/meshes/m0609_white/MF0609_2_0.dae" scale="0.001 0.001 0.001" />
				</geometry>
			</visual>
			<collision>
				<origin rpy="0 0 0" xyz="0 0 0" />
				<geometry>
					<mesh filename="/home/rokey/dev_ws/issac_sim/src/doosan-robot2/urdf/meshes/m0609_collision/MF0609_2_1.dae" scale="0.001 0.001 0.001" />
				</geometry>
			</collision>
			<visual>
				<origin rpy="0 0 0" xyz="0 0 0" />
				<geometry>
					<mesh filename="/home/rokey/dev_ws/issac_sim/src/doosan-robot2/urdf/meshes/m0609_white/MF0609_2_1.dae" scale="0.001 0.001 0.001" />
				</geometry>
			</visual>
			<collision>
				<origin rpy="0 0 0" xyz="0 0 0" />
				<geometry>
					<mesh filename="/home/rokey/dev_ws/issac_sim/src/doosan-robot2/urdf/meshes/m0609_collision/MF0609_2_2.dae" scale="0.001 0.001 0.001" />
				</geometry>
			</collision>
			<visual>
				<origin rpy="0 0 0" xyz="0 0 0" />
				<geometry>
					<mesh filename="/home/rokey/dev_ws/issac_sim/src/doosan-robot2/urdf/meshes/m0609_white/MF0609_2_2.dae" scale="0.001 0.001 0.001" />
				</geometry>
			</visual>
		</link>
		<!-- joint3 -->
		<joint name="joint_3" type="revolute">
			<parent link="link_2" />
			<child link="link_3" />
			<origin rpy="0 0 1.571" xyz="0.411 0 0" />
			<axis xyz="0 0 1" />
			<limit effort="5400" lower="-2.618" upper="2.618" velocity="3.1416"/>
			<dynamics friction="0"  damping="15" stiffness="150"/>
		</joint>
		<link name="link_3">
			<inertial>
				<mass value="3.6"/>
				<origin xyz="-2.2e-05   -0.006867    0.043445"/>
				<inertia ixx="0.018342" ixy="1.1302e-05" ixz="-4.5308e-06" iyy="0.018239"
					iyz="-0.00099247"
					izz="0.01326"/>
			</inertial>
			<collision>
				<origin rpy="0 0 0" xyz="0 0 0" />
				<geometry>
					<mesh filename="/home/rokey/dev_ws/issac_sim/src/doosan-robot2/urdf/meshes/m0609_collision/MF0609_3_0.dae" scale="0.001 0.001 0.001" />
				</geometry>
			</collision>
			<visual>
				<origin rpy="0 0 0" xyz="0 0 0" />
				<geometry>
					<mesh filename="/home/rokey/dev_ws/issac_sim/src/doosan-robot2/urdf/meshes/m0609_white/MF0609_3_0.dae" scale="0.001 0.001 0.001" />
				</geometry>
			</visual>
		</link>
		<!-- joint4 -->
		<joint name="joint_4" type="revolute">
			<parent link="link_3" />
			<child link="link_4" />
			<origin rpy="1.571 0 0" xyz="0 -0.368 0" />
			<axis xyz="0 0 1" />
			<limit effort="2700" lower="-6.2832" upper="6.2832" velocity="3.927"/>
			<dynamics friction="0"  damping="7.5" stiffness="750"/>
		</joint>
		<link name="link_4">
			<inertial>
				<mass value="3.57"/>
				<origin xyz="4e-05    0.097079    -0.10981"/>
				<inertia ixx="0.08035" ixy="-4.6119e-06" ixz="-8.1798e-06" iyy="0.066005"
					iyz="-0.028996"
					izz="0.029763"/>
			</inertial>
            <collision>
				<origin rpy="0 0 0" xyz="0 0 0" />
				<geometry>
					<mesh filename="/home/rokey/dev_ws/issac_sim/src/doosan-robot2/urdf/meshes/m0609_collision/MF0609_4_0.dae" scale="0.001 0.001 0.001" />
				</geometry>
			</collision>
			<visual>
				<origin rpy="0 0 0" xyz="0 0 0" />
				<geometry>
					<mesh filename="/home/rokey/dev_ws/issac_sim/src/doosan-robot2/urdf/meshes/m0609_white/MF0609_4_0.dae" scale="0.001 0.001 0.001" />
				</geometry>
			</visual>
			<collision>
				<origin rpy="0 0 0" xyz="0 0 0" />
				<geometry>
					<mesh filename="/home/rokey/dev_ws/issac_sim/src/doosan-robot2/urdf/meshes/m0609_collision/MF0609_4_1.dae" scale="0.001 0.001 0.001" />
				</geometry>
			</collision>
			<visual>
				<origin rpy="0 0 0" xyz="0 0 0" />
				<geometry>
					<mesh filename="/home/rokey/dev_ws/issac_sim/src/doosan-robot2/urdf/meshes/m0609_white/MF0609_4_1.dae" scale="0.001 0.001 0.001" />
				</geometry>
			</visual>
		</link>
		<!-- joint5 -->
		<joint name="joint_5" type="revolute">
			<parent link="link_4" />
			<child link="link_5" />
			<origin rpy="-1.571 0 0" xyz="0 0 0" />
			<axis xyz="0 0 1" />
			<limit effort="2700" lower="-6.2832" upper="6.2832" velocity="3.927"/>
			<dynamics friction="0"   damping="7.5" stiffness="750"/>
		</joint>
		<link name="link_5">
			<inertial>
				<mass value="2.83"/>
				<origin xyz="-6.8e-05    0.003827    0.031969"/>
				<inertia ixx="0.014275" ixy="2.2026e-05" ixz="3.3017e-06" iyy="0.012569"
					iyz="0.00045077"
					izz="0.0085318"/>
			</inertial>
            <collision>
				<origin rpy="0 0 0" xyz="0 0 0" />
				<geometry>
					<mesh filename="/home/rokey/dev_ws/issac_sim/src/doosan-robot2/urdf/meshes/m0609_collision/MF0609_5_0.dae" scale="0.001 0.001 0.001" />
				</geometry>
			</collision>
			<visual>
				<origin rpy="0 0 0" xyz="0 0 0" />
				<geometry>
					<mesh filename="/home/rokey/dev_ws/issac_sim/src/doosan-robot2/urdf/meshes/m0609_white/MF0609_5_0.dae" scale="0.001 0.001 0.001" />
				</geometry>
			</visual>
		</link>
		<!-- joint6 -->
		<joint name="joint_6" type="revolute">
			<parent link="link_5" />
			<child link="link_6" />
			<origin rpy="1.571 0 0" xyz="0 -0.121 0" />
			<axis xyz="0 0 1" />
			<limit effort="2700" lower="-6.2832" upper="6.2832" velocity="3.927"/>
			<dynamics friction="0"   damping="7.5" stiffness="750"/>
		</joint>
		<link name="link_6">
			<inertial>
				<mass value="1.16"/>
				<origin xyz="-3e-05    -4.5e-05     -0.0539"/>
				<inertia ixx="0.0080226" ixy="1.371e-06" ixz="6.3578e-06" iyy="0.0053992"
					iyz="7.4676e-06"
					izz="0.0053912"/>
			</inertial>
			<collision>
				<origin rpy="0 0 0" xyz="0 0 0" />
				<geometry>
					<mesh filename="/home/rokey/dev_ws/issac_sim/src/doosan-robot2/urdf/meshes/m0609_collision/MF0609_6_0.dae" scale="0.001 0.001 0.001" />
				</geometry>
			</collision>
			<visual>
				<origin rpy="0 0 0" xyz="0 0 0" />
				<geometry>
					<mesh filename="/home/rokey/dev_ws/issac_sim/src/doosan-robot2/urdf/meshes/m0609_white/MF0609_6_0.dae" scale="0.001 0.001 0.001" />
				</geometry>
			</visual>
		</link>
		<link name="tool0"/>
		<joint name="joint_6-tool0" type="fixed">
			<origin rpy="0 0 0" xyz="0 0 0"/>
			<parent link="link_6"/>
			<child link="tool0"/>
		</joint>




    <joint name="m0609_rg2_mount" type="fixed">
        <parent link="link_6"/>
        <child link="quick_changer"/>
        <origin rpy="0 0 0" xyz="0 0 0"/>
    </joint>


  
  <!-- These joints closes the kinematic loop. Since loops are not allowed in URDF, but they are
      allowed in SDF, this is an SDF fragment. -->
  
  
  <!-- Mimic joint plugin -->
  
  
  
  
  
  
  
  
  
  
  
  
  
  
  
  
  
  
  <material name="silver">
    <color rgba="0.700 0.700 0.700 1.000"/>
  </material>
  <material name="blue">
    <color rgba="0.21568627450980393 0.592156862745098 0.8117647058823529 1.000"/>
  </material>
  <link name="quick_changer">
    <inertial>
      <origin rpy="0 0 0" xyz="0.0014673787228634701 -0.0007395056519161622 0.00391087859435364"/>
      <mass value="0.05802030412577654"/>
      <inertia ixx="2e-05" ixy="-0.0" ixz="-0.0" iyy="2.7e-05" iyz="0.0" izz="4.5e-05"/>
    </inertial>
    <visual>
      <origin rpy="0 0 0" xyz="0 0 0"/>
      <geometry>
        <mesh filename="/home/rokey/dev_ws/issac_sim/src/onrobot_rg2/meshes/visual/quick_changer.stl" scale="0.001 0.001 0.001"/>
      </geometry>
      <material name="blue"/>
    </visual>
    <collision>
      <origin rpy="0 0 0" xyz="0 0 0"/>
      <geometry>
        <mesh filename="/home/rokey/dev_ws/issac_sim/src/onrobot_rg2/meshes/collision/quick_changer.stl" scale="0.001 0.001 0.001"/>
      </geometry>
    </collision>
  </link>
  <link name="gripper_body">
    <inertial>
      <origin rpy="0 0 0" xyz="0.0272971231150397 -0.002438088956580745 0.035297715994502724"/>
      <mass value="0.5707794664902835"/>
      <inertia ixx="0.000622" ixy="3e-06" ixz="0.0" iyy="0.000662" iyz="1.8e-05" izz="0.000226"/>
    </inertial>
    <visual>
      <origin rpy="0 0 0" xyz="0.02705 -0.0 -0.047"/>
      <geometry>
        <mesh filename="/home/rokey/dev_ws/issac_sim/src/onrobot_rg2/meshes/visual/gripper_body.stl" scale="0.001 0.001 0.001"/>
      </geometry>
      <material name="silver"/>
    </visual>
    <collision>
      <origin rpy="0 0 0" xyz="0.02705 -0.0 -0.047"/>
      <geometry>
        <mesh filename="/home/rokey/dev_ws/issac_sim/src/onrobot_rg2/meshes/collision/gripper_body.stl" scale="0.001 0.001 0.001"/>
      </geometry>
    </collision>
  </link>
  <link name="angle_bracket">
    <inertial>
      <origin rpy="0 0 0" xyz="-0.00023577776357350244 0.0006406606087327927 0.01993861451986476"/>
      <mass value="0.19757034519537245"/>
      <inertia ixx="9.8e-05" ixy="-0.0" ixz="-1e-06" iyy="0.000145" iyz="2e-06" izz="0.000155"/>
    </inertial>
    <visual>
      <origin rpy="0 0 0" xyz="-0.0 -0.0 -0.00255"/>
      <geometry>
        <mesh filename="/home/rokey/dev_ws/issac_sim/src/onrobot_rg2/meshes/visual/angle_bracket.stl" scale="0.001 0.001 0.001"/>
      </geometry>
      <material name="silver"/>
    </visual>
    <collision>
      <origin rpy="0 0 0" xyz="-0.0 -0.0 -0.00255"/>
      <geometry>
        <mesh filename="/home/rokey/dev_ws/issac_sim/src/onrobot_rg2/meshes/collision/angle_bracket.stl" scale="0.001 0.001 0.001"/>
      </geometry>
    </collision>
  </link>
  <link name="left_inner_knuckle">
    <inertial>
      <origin rpy="0 0 0" xyz="0.01762916513992015 0.010471874847992522 0.017068183318320468"/>
      <mass value="0.024337519273275633"/>
      <inertia ixx="5e-06" ixy="-0.0" ixz="-3e-06" iyy="7e-06" iyz="-0.0" izz="5e-06"/>
    </inertial>
    <visual>
      <origin rpy="0 0 0" xyz="-0.0075 0.009367 -0.139397"/>
      <geometry>
        <mesh filename="/home/rokey/dev_ws/issac_sim/src/onrobot_rg2/meshes/visual/left_inner_knuckle.stl" scale="0.001 0.001 0.001"/>
      </geometry>
      <material name="silver"/>
    </visual>
    <collision>
      <origin rpy="0 0 0" xyz="-0.0075 0.009367 -0.139397"/>
      <geometry>
        <mesh filename="/home/rokey/dev_ws/issac_sim/src/onrobot_rg2/meshes/collision/left_inner_knuckle.stl" scale="0.001 0.001 0.001"/>
      </geometry>
    </collision>
  </link>
  <link name="right_outer_knuckle">
    <inertial>
      <origin rpy="0 0 0" xyz="-0.012312223780380358 0.010369678145266329 0.010203759185649544"/>
      <mass value="0.041583686281793396"/>
      <inertia ixx="1e-05" ixy="0.0" ixz="7e-06" iyy="1.6e-05" iyz="-0.0" izz="1e-05"/>
    </inertial>
    <visual>
      <origin rpy="0 0 0" xyz="0.017 0.009534 -0.122898"/>
      <geometry>
        <mesh filename="/home/rokey/dev_ws/issac_sim/src/onrobot_rg2/meshes/visual/right_outer_knuckle.stl" scale="0.001 0.001 0.001"/>
      </geometry>
      <material name="silver"/>
    </visual>
    <collision>
      <origin rpy="0 0 0" xyz="0.017 0.009534 -0.122898"/>
      <geometry>
        <mesh filename="/home/rokey/dev_ws/issac_sim/src/onrobot_rg2/meshes/collision/right_outer_knuckle.stl" scale="0.001 0.001 0.001"/>
      </geometry>
    </collision>
  </link>
  <link name="left_outer_knuckle">
    <inertial>
      <origin rpy="0 0 0" xyz="0.01231204747983699 0.010369678145260136 0.01020375918419171"/>
      <mass value="0.04158368628179342"/>
      <inertia ixx="1e-05" ixy="-0.0" ixz="-7e-06" iyy="1.6e-05" iyz="-0.0" izz="1e-05"/>
    </inertial>
    <visual>
      <origin rpy="0 0 0" xyz="-0.017 0.009534 -0.122898"/>
      <geometry>
        <mesh filename="/home/rokey/dev_ws/issac_sim/src/onrobot_rg2/meshes/visual/left_outer_knuckle.stl" scale="0.001 0.001 0.001"/>
      </geometry>
      <material name="silver"/>
    </visual>
    <collision>
      <origin rpy="0 0 0" xyz="-0.017 0.009534 -0.122898"/>
      <geometry>
        <mesh filename="/home/rokey/dev_ws/issac_sim/src/onrobot_rg2/meshes/collision/left_outer_knuckle.stl" scale="0.001 0.001 0.001"/>
      </geometry>
    </collision>
  </link>
  <link name="left_inner_finger">
    <inertial>
      <origin rpy="0 0 0" xyz="-0.009341477027312806 0.006108535220686467 0.03133683897712786"/>
      <mass value="0.03203868115594587"/>
      <inertia ixx="9e-06" ixy="0.0" ixz="2e-06" iyy="9e-06" iyz="-0.0" izz="2e-06"/>
    </inertial>
    <visual>
      <origin rpy="0 0 0" xyz="-0.056748 0.00475 -0.160866"/>
      <geometry>
        <mesh filename="/home/rokey/dev_ws/issac_sim/src/onrobot_rg2/meshes/visual/left_inner_finger.stl" scale="0.001 0.001 0.001"/>
      </geometry>
      <material name="silver"/>
    </visual>
    
  </link>
  <link name="right_inner_finger">
    <inertial>
      <origin rpy="0 0 0" xyz="0.009341300963273541 0.006108535097342211 0.03133683984830843"/>
      <mass value="0.032038680057528524"/>
      <inertia ixx="9e-06" ixy="-0.0" ixz="-2e-06" iyy="9e-06" iyz="-0.0" izz="2e-06"/>
    </inertial>
    <visual>
      <origin rpy="0 0 0" xyz="0.056748 0.00475 -0.160866"/>
      <geometry>
        <mesh filename="/home/rokey/dev_ws/issac_sim/src/onrobot_rg2/meshes/visual/right_inner_finger.stl" scale="0.001 0.001 0.001"/>
      </geometry>
      <material name="silver"/>
    </visual>
    
  </link>
  <link name="right_inner_knuckle">
    <inertial>
      <origin rpy="0 0 0" xyz="-0.017629341439301484 0.010471874848001397 0.017068183319570135"/>
      <mass value="0.024337519273275623"/>
      <inertia ixx="5e-06" ixy="0.0" ixz="3e-06" iyy="7e-06" iyz="-0.0" izz="5e-06"/>
    </inertial>
    <visual>
      <origin rpy="0 0 0" xyz="0.0075 0.009367 -0.139397"/>
      <geometry>
        <mesh filename="/home/rokey/dev_ws/issac_sim/src/onrobot_rg2/meshes/visual/right_inner_knuckle.stl" scale="0.001 0.001 0.001"/>
      </geometry>
      <material name="silver"/>
    </visual>
    <collision>
      <origin rpy="0 0 0" xyz="0.0075 0.009367 -0.139397"/>
      <geometry>
        <mesh filename="/home/rokey/dev_ws/issac_sim/src/onrobot_rg2/meshes/collision/right_inner_knuckle.stl" scale="0.001 0.001 0.001"/>
      </geometry>
    </collision>
  </link>
  
  <joint name="gripper_body_joint" type="fixed">
    <origin rpy="0.010122909661567111 0 0" xyz="-0.02705 0.0 0.04445"/>
    <parent link="angle_bracket"/>
    <child link="gripper_body"/>
  </joint>
  <joint name="angle_bracket_joint" type="fixed">
    <origin rpy="0 0 0" xyz="0.0 0.0 0.00255"/>
    <parent link="quick_changer"/>
    <child link="angle_bracket"/>
  </joint>
  <joint name="left_inner_knuckle_joint" type="fixed">
    <origin rpy="0 0.4153883619746504 0" xyz="0.03455 -0.009367 0.092397"/>
    <parent link="gripper_body"/>
    <child link="left_inner_knuckle"/>
    <axis xyz="-0.0 0.999949 -0.010122"/>
    <limit effort="50.0" lower="-1.19" upper="0.01" velocity="2.0"/>
    <mimic joint="finger_joint" multiplier="-1" offset="0"/>
  </joint>
  <joint name="finger_joint" type="revolute">
    <origin rpy="0 -0.4153883619746504 0" xyz="0.01005 -0.009534 0.075898"/>
    <parent link="gripper_body"/>
    <child link="right_outer_knuckle"/>
    <axis xyz="-0.0 0.999949 -0.010122"/>
    <limit effort="50.0" lower="0" upper="1.18" velocity="2.0"/>
  </joint>
  <joint name="left_outer_knuckle_joint" type="revolute">
    <origin rpy="0 0.4153883619746504 0" xyz="0.04405 -0.009534 0.075898"/>
    <parent link="gripper_body"/>
    <child link="left_outer_knuckle"/>
    <axis xyz="-0.0 0.999949 -0.010122"/>
    <limit effort="50.0" lower="-1.19" upper="0.01" velocity="2.0"/>
    <mimic joint="finger_joint" multiplier="-1" offset="0"/>
  </joint>
  <joint name="left_inner_finger_joint" type="fixed">
    <origin rpy="0 -0.4153883619746504 0" xyz="0.039748 0.004784 0.037968"/>
    <parent link="left_outer_knuckle"/>
    <child link="left_inner_finger"/>
    <axis xyz="0.0 -0.999949 0.010122"/>
    <limit effort="50.0" lower="-1.19" upper="0.01" velocity="2.0"/>
    <mimic joint="finger_joint" multiplier="-1" offset="0"/>
  </joint>
  <joint name="right_inner_finger_joint" type="fixed">
    <origin rpy="0 0.4153883619746504 0" xyz="-0.039748 0.004784 0.037968"/>
    <parent link="right_outer_knuckle"/>
    <child link="right_inner_finger"/>
    <axis xyz="0.0 0.999949 -0.010122"/>
    <limit effort="50.0" lower="-1.19" upper="0.01" velocity="2.0"/>
    <mimic joint="finger_joint" multiplier="-1" offset="0"/>
  </joint>
  <joint name="right_inner_knuckle_joint" type="fixed">
    <origin rpy="0 -0.4153883619746504 0" xyz="0.01955 -0.009367 0.092397"/>
    <parent link="gripper_body"/>
    <child link="right_inner_knuckle"/>
    <axis xyz="-0.0 0.999949 -0.010122"/>
    <limit effort="50.0" lower="-0.01" upper="1.19" velocity="2.0"/>
    <mimic joint="finger_joint" multiplier="1" offset="0"/>
  </joint>
  
  

    <link name="right_phantom_pad">
        <inertial>
            <origin rpy="0 0 0" xyz="0 0 0"/>
            <mass value="0.001"/>
            <inertia ixx="1e-7" ixy="0" ixz="0" iyy="1e-7" iyz="0" izz="1e-7"/>
        </inertial>
        <collision>
            <origin rpy="0 -1.150000 0" xyz="-0.020 0 0.080"/>
            <geometry>
                <box size="0.005 0.030 0.080"/>
            </geometry>
        </collision>
    </link>
    <joint name="right_phantom_pad_joint" type="fixed">
        <parent link="right_outer_knuckle"/>
        <child link="right_phantom_pad"/>
        <origin rpy="0 0 0" xyz="0 0 0"/>
    </joint>

    <link name="left_phantom_pad">
        <inertial>
            <origin rpy="0 0 0" xyz="0 0 0"/>
            <mass value="0.001"/>
            <inertia ixx="1e-7" ixy="0" ixz="0" iyy="1e-7" iyz="0" izz="1e-7"/>
        </inertial>
        <collision>
            <origin rpy="0 1.150000 0" xyz="0.020 0 0.080"/>
            <geometry>
                <box size="0.005 0.030 0.080"/>
            </geometry>
        </collision>
    </link>
    <joint name="left_phantom_pad_joint" type="fixed">
        <parent link="left_outer_knuckle"/>
        <child link="left_phantom_pad"/>
        <origin rpy="0 0 0" xyz="0 0 0"/>
    </joint>


    <link name="fingertip_center"/>
    <joint name="fingertip_center_joint" type="fixed">
        <parent link="gripper_body"/>
        <child link="fingertip_center"/>
        <origin rpy="0 0 0" xyz="0.02705 -0.00953 0.11387"/>
    </joint>

</robot>
